Workbook
Name _ftnref3: 'Carbon Reduction Plan Report'!$A$64
Name OLE_LINK2: '2024 Results Graphs'!#REF!
Name OLE_LINK3: '2024 Results Graphs'!#REF!

Sheet General Info
A1: Please complete relevant areas/fields when applicable. If you require assistance please email: info@sustainquality.co.uk
A3: Login details
A4: Login details
A5: Password
A6: send email to confirm before allowing access
A8: Contact Name
A9: Email
A10: Location (country)
A11: How many organisations?
A13: Organisation Details
A14: Organisation Name
A15: Organisation Address (Registered address)
A16: Sector | D16: Private, Public, Third | E16: we may introduce a paywall if private and public start to use it
A17: Sub-sector | F17: The four main Sub Sectors of an economy are:
A18: Industry (SIC if available) | D18: https://companieshouse.blog.gov.uk/2021/10/12/choosing-a-standard-industrial-classification-sic-code-for-your-company/ | F18: Primary sector: Represents companies that are involved in extracting natural resources and agriculture.
A19: How many buildings to be assessed? | F19: Secondary sector: Companies involved in manufacturing, construction, and processing producing goods that use the resources obtained from companies within the primary sector.
A20: Would you like to include events (if yes - check line 72 for data entry for each event)? | F20: Tertiary sector: Companies that provide services such as entertainment, financial, and retailers.
A21: How many events would you like to include? | D21: events treated as 'new buildings' | F21: Quaternary sector: Involves knowledge-based activities such as information technology, research, and development, as well as consulting services and education.
A23: Full Address - Asset 1 | C23: Description
A24: Is it the Registered office? | C24: (YES or NO)
A25: Name of Asset/Property Group
A26: note: the name of the asset entered here will appear above the assets address on any certificates produced for this asset. Certificate shows a maximum of 28 characters.
A27: Address line 1
A28: Address line 2
A29: note: address line 1 and 2 will be combined as a single line on the certificate and a maximum of 28 charcters will be shown
A30: Address line 3
A31: Address line 4
A32: Note: Address line 3 and 4 will be continued as a single line on the certificate and a maximum of 28 characters will be shown
A33: Town/City
A34: County/Region/State
A35: Post code
A36: Building floor Area (m2) | C36: =C60 -> 0 | D36: Please complete Asset dimensions below
A37: Include in the offset calculation?
A39: Basic building details - Asset 1 | C39: Description
A40: Name of the organisation or peson that owns the asset
A41: Name of the organisation or peson that manages the tenancy of the asset
A42: Name of the organisation or peson that occupies/leases the asset
A43: Assest Description (up to 500 characters)
A44: Add other stakeholders (Sustainability Consultant, MEP, partners…)
A46: General information - Asset 1 | C46: Description
...

Sheet Assessment Scope
A1: Please complete relevant areas/fields when applicable. If you require assistance please emai:l info@sustainquality.co.uk
A3: Organisation Details
A4: Organisation Name (Client/owner) | C4: ='General Info'!C14 -> 0
A5: Organisation Address (head quarters/Main address) | C5: ='General Info'!C15 -> 0
A6: How many buildings included/assessed? | C6: ='General Info'!C19 -> 0
A8: General NOTES - All assets or clearly state which assets | C8: Description
A9: Extra note to the reports 1 | D9: User to input text (any words/character limit?)
A10: Extra note to the reports 2 | D10: User to input text (any words/character limit?)
A12: Quantified Carbon Emissions | C12: (Yes or No) | D12: Notes and justificaiton | E12: Check results graph tab line125 If marked Yes should show in the Quantified - if marked Non should show in the non-quantified | M12: Check list | O12: Data included
A13: Base year | D13: Add commentary regarding your Baseline Emissions as required: e.g. historic baseline which deviates from the requirements under this measure (e.g. no prior Scope 3 emissions reporting), where there is no previous reporting and the creation of a new baseline due to substantial organisational change or restructuring] | E13: Year | M13: Base year
A14: Commitiment to achieve Net Zero | E14: Year
A15: Energy | C15: Yes | E15: This will unlock the respective tab | M15: Energy
A16: Water | C16: yes | M16: Water
A17: Waste | C17: No | M17: Waste
A18: Business and Staff Travel | C18: Yes | M18: Business and Staff Travel
A19: Refrigerant | C19: No | M19: Refrigerant
A20: Hotel Stay | C20: No | M20: Hotel Stay
A21: Working from Home | C21: Yes | M21: Working from Home
A22: Materials | C22: No | M22: Materials
A23: Carbon Reduction Plan | M23: Carbon Reduction Plan
A24: Off set strategy
A25: Are there specific processing or activities that emiits carbon not listed above? If yes, please elaborate and submitt for review and implementation
O26: SUBMIT ASSESSMENT FOR REVIEW
A27: Standards Policies in Place (All assets or clearly state which assets)? | C27: (Yes or No)
A28: Environment Policy (accredited to ISO 14001) | F28: https://www.iso.org/standard/60857.html
A29: Human Rights Policy
A30: Sustainable Procurement Policy (ISO 20400) | F30: https://www.iso.org/standard/63026.html
A31: Energy Audit (ISO5002) | F31: https://www.iso.org/standard/60088.html
A32: Has the orgnisation not utilised any ozone-depletio substances (ODS - GRI Commitment)? | D32: As of January 2010, in line with the Montreal Protocol, ODS were prohibted and severely controlled. As such this organisation has no affiliation or use with these substances and are committed to reduce atmospheric emissions in this way.
A33: Add other standard required
A35: International Standards | C35: (Yes or No) | D35: Which Assets?
A36: Eco Audit action plan | F36: https://www.citybridgefoundation.org.uk/funding/eco-audits
A37: BREEAM In-use Part 2 | F37: https://bregroup.com/products/breeam/breeam-technical-standards/breeam-in-use/
A38: Carbon Reduction Plan | F38: https://assets.publishing.service.gov.uk/media/60ba4d208fa8f57ce980b5b7/PPN_0621_Technical_standard_for_the_Completion_of_Carbon_Reduction_Plans__2_.pdf
A39: Science Based Targets | E39: under development | F39: https://sciencebasedtargets.org
A40: CIBSE BENCHMARK | E40: under development | F40: https://www.cibse.org/knowledge-research/knowledge-resources/knowledge-toolbox/benchmarking-registration
A41: Fitwell | E41: under development | F41: https://www.fitwel.org
A42: CRREM (EU) | E42: under development | F42: https://www.crrem.eu
A43: NABERS UK (offices only) | E43: under development | F43: https://bregroup.com/products/nabers-uk/
A44: GRESB | E44: under development | F44: https://www.gresb.com/
...

Sheet Energy
A1: ENERGY USE
B2: Two options (19 - Calendar or 19 - Financial | F2: conv facto from gov 2023
A3: Period | B3: April 2019 - March 2020 | C3: April 2020 - March 2021 | D3: April 2021 - March 2022 | E3: April 2022 - March 2023 | F3: April 2023 - March 2024 | G3: April 2024 - March 2025 | H3: financial year/ full year - specify the months of data provided
A4: Data Input | B4: Two options (Montly or Annual)
A5: If annual | B5: CONSUMPTION | C5: CONSUMPTION | D5: CONSUMPTION | E5: CONSUMPTION | F5: CONSUMPTION
A6: Mains electricity use | H6: kWh | I6: Electricity use in kWh can be found on your electricity bills.
A7: Mains gas use | H7: kWh | I7: Gas use in kWh can be found on your gas bills.
A8: Diesel use | H8: Litres | I8: If the venue uses diesel powered generators as part of its permanent energy supply, provide the amount of diesel used.
A9: Bottled gas use | H9: litres | I9: LPG gas bottles (Propane & Butane)
A10: Oil use | H10: litres | I10: If the venue uses oil powered generators as part of its permanent energy supply, provide the amount of oil used.
A11: Other (specify i.e District Heating) | H11: kWh or % | I11: Please find energy used from district heating
A12: Provide conversion factor for other | H12: Unit | I12: Please provide document confirming the converstion factor of the district heating
A13: Onsite renewable energy | H13: kWh | I13: If you have any renewable energy sources on your building, such as photovoltaic (PV) panels, provide the kWh of energy produced.
A16: Energy supplier
A17: Electricity supplier | I17: Provide the electricty supplier company name
A19: Green electricity tariff | H19: yes/no/don’t know | I19: All suppliers in the UK get at least some of their electricity from renewable sources and most offer what's known as 'green' tariff electricity. If you are on such tariff, it means one of two things: 1 - The supplier promises to match your usage with generation from renewable sources, and invest in additional generation or contribute to envrionmental schemes that lower carbon dioxide emissions (a 'green' tariff with additionality) 2 - The supplier promises to match your usage with generation from renewable sources, but doens't offer any additional envrionmental benefits (a 'green' tariff without additionality)
A21: Energy use notes
A22: Green electricity tariff details | I22: If you use one, please give details of your green electricity tariff supplier and the tariff name. A green electricity tariff is a tariff that the enery suppler claims has environmental benefits.
A24: Energy notes | I24: Please add any notes about your data sources and assumptions fo energy estimates
A28: Custom Emissions
A29: Description | H29: Emissions (kg CO2e) | K29: If you have calculated your emissions elswhere, please include them here.
A32: Attach files
A33: Please attach energy bills (a sample including the first and the last bill during the period
A37: CLICK HERE TO SUBMIT FOR REVIEW
A39: If monthly
A40: If Finacial Year
A41: Montly Input | B41: April | C41: May | D41: June | E41: July | F41: August | G41: September | H41: October | I41: November | J41: December | K41: January | L41: February | M41: March | N41: Total
A42: Mains electricity use | N42: =SUM(B42:M42) -> 0
A43: Mains gas use | N43: =SUM(B43:M43) -> 0
A44: Diesel use | N44: =SUM(B44:M44) -> 0
A45: Bottled gas use | N45: =SUM(B45:M45) -> 0
A46: Oil use | N46: =SUM(B46:M46) -> 0
A47: Other (specify i.e District Heating) | N47: =SUM(B47:M47) -> 0
A48: Provide conversion factor for other | N48: =SUM(B48:M48) -> 0
A49: Onsite renewable energy | N49: =SUM(B49:M49) -> 0
A51: If Calendar Year
A52: Montly Input | B52: January | C52: February | D52: March | E52: April | F52: May | G52: June | H52: July | I52: August | J52: September | K52: October | L52: November | M52: December | N52: Total
A53: Mains electricity use | N53: =SUM(B53:M53) -> 0
A54: Mains gas use | N54: =SUM(B54:M54) -> 0
A55: Diesel use | N55: =SUM(B55:M55) -> 0
...

Sheet Water
A1: WATER CONSUMPTION
C2: Two options (19 - Calendar or 19 - Financial
A3: Period | C3: April 2019 - March 2020 | D3: April 2020 - March 2021 | E3: April 2021 - March 2022 | F3: April 2022 - March 2023 | G3: April 2023 - March 2024 | H3: April 2024 - March 2025 | I3: financial year/ full year - specify the months of data provided
A4: Data Input | C4: Two options (Montly or Annual)
A5: If annual | C5: CONSUMPTION | D5: CONSUMPTION | E5: CONSUMPTION | F5: CONSUMPTION | G5: CONSUMPTION | H5: CONSUMPTION
A6: Water use | I6: m3 | J6: Water use in m3 can be found on your water bills. If it is in litres, divide by 1,000. For venue hire, the venue should provide the submeter reading.
A8: Wastewater | I8: m3 | J8: Sewerage or wastewater in m3 can be found on your water or sewerage bills. It it is in litres, divide by 1,000. If you can't find sewerage data, then assume it's the same as your water use.
A11: Water notes | J11: Please add notes related to water data sources and assumptions
A14: Custom Emissions
A15: Description | I15: Emissions (kg CO2e) | K15: If you have calculated your emissions elswhere, please include them here.
A18: Attach files
A19: Please attach water bills (a sample including the first and the last bill during the period
A23: CLICK HERE TO SUBMIT FOR REVIEW
A25: If monthly
A26: If Finacial Year
A27: Montly Input | B27: April | C27: May | D27: June | E27: July | F27: August | G27: September | H27: October | I27: November | J27: December | K27: January | L27: February | M27: March | N27: Total
A28: Water Use | N28: =SUM(B28:M28) -> 0
A29: Waste Water | N29: =SUM(B29:M29) -> 0
A31: If Calendar Year
A32: Montly Input | B32: January | C32: February | D32: March | E32: April | F32: May | G32: June | H32: July | I32: August | J32: September | K32: October | L32: November | M32: December | N32: Total
A33: Water Use | N33: =SUM(B33:M33) -> 0
A34: Waste Water | N34: =SUM(B34:M34) -> 0

Sheet Waste 
A1: WASTE GENERATION
C2: Two options (19 - Calendar or 19 - Financial
A3: Period | C3: April 2019 - March 2020 | D3: April 2020 - March 2021 | E3: April 2021 - March 2022 | F3: April 2022 - March 2023 | G3: April 2023 - March 2024 | H3: April 2024 - March 2025 | I3: financial year/ full year - specify the months of data provided
A4: Data Input | C4: Two options (Montly or Annual)
C5: Data input in tonnes only - Go to Waste Calculator if data is in Bag, Litres or Kilograms
A7: If annual | C7: CONSUMPTION | D7: CONSUMPTION | E7: CONSUMPTION | F7: CONSUMPTION | G7: CONSUMPTION | H7: CONSUMPTION
A8: Waste to landfill | I8: Unit | K8: Tonnage can be found on the bills from your waste contractor. If not, estimate the number of black bin bags sent to landfill each week. | M8: UNIT CONVERSION
N9: bags --> kg | O9: litres --> kg | P9: KG to Tonnes
A10: Waste to energy | I10: Unit | K10: Tonnage can be found on the bills from your waste contractor. If not, estimate the number of black bin bags sent to landfill each week. | M10: General Waste | N10: 5.0192308 | O10: 0.08365385 | P10: 0.001
M11: Recycling | N11: 4.0980392 | O11: 0.06830065 | P11: 0.001
A12: Waste to recycling | I12: Unit | K12: Tonnage can be found on the bills from your waste contractor. If not, estimate the number of black bin bags sent to landfill each week. | M12: Mixed Food | N12: 19.057692 | O12: 0.3176281 | P12: 0.001
A14: Waste to composting | I14: Unit | K14: Tonnage can be found on the bills from your waste contractor. If not, estimate the number of black bin bags sent to landfill each week.
A19: Waste notes | K19: Please add notes related to waste data sources and assumptions
A23: Custom Emissions
A24: Description | I24: Emissions (kg CO2e) | K24: If you have calculated your emissions elswhere, please include them here.
A27: Attach files
A28: Please attach waste bills/tickets/reports (a sample including the first and the last bill during the period
A33: CLICK HERE TO SUBMIT FOR REVIEW
A35: If monthly
A36: If Finacial Year
A37: Montly Input | B37: April | C37: May | D37: June | E37: July | F37: August | G37: September | H37: October | I37: November | J37: December | K37: January | L37: February | M37: March | N37: Total
A38: Waste to landfill | N38: =SUM(B38:M38) -> 0
A39: Waste to energy | N39: =SUM(B39:M39) -> 0
A40: Waste to recycling | N40: =SUM(B40:M40) -> 0
A41: Waste to composting | N41: =SUM(B41:M41) -> 0
A43: If Calendar Year
A44: Montly Input | B44: January | C44: February | D44: March | E44: April | F44: May | G44: June | H44: July | I44: August | J44: September | K44: October | L44: November | M44: December | N44: Total
A45: Waste to landfill | N45: =SUM(B45:M45) -> 0
A46: Waste to energy | N46: =SUM(B46:M46) -> 0
A47: Waste to recycling | N47: =SUM(B47:M47) -> 0
A48: Waste to composting | N48: =SUM(B48:M48) -> 0

Sheet Business & Staff Travel
B1: BUSINESS TRAVEL
D2: Two options (19 - Calendar or 19 - Financial
B3: Period | D3: April 2019 - March 2020 | E3: April 2020 - March 2021 | F3: April 2021 - March 2022 | G3: April 2022 - March 2023 | H3: April 2023 - March 2024 | I3: April 2024 - March 2025 | J3: financial year/ full year - specify the months of data provided | M3: April 2019 - March 2020 | N3: April 2020 - March 2021 | O3: April 2021 - March 2022 | P3: April 2022 - March 2023 | Q3: April 2023 - March 2024 | R3: April 2024 - March 2025 | S3: financial year/ full year - specify the months of data provided
B4: Data Input | D4: Two options (Montly or Annual)
B5: Unit input | D5: Miles or KM
B6: How do you define domestic, short-haul, long-haul and international flights?
B7: Broadly speaking the definition of domestic flights, are those within the UK, short-haul are those within Europe, long-haul are outside of Europe and international flights are those between non-UK destinations. A full list of countries and their assignment to either long-haul or short-haul is provided in the Haul_definition tab.
B9: Please complete the data in Km and remove the 0. If your data is in Miles, please complete the column Miles and the calculator will convert KM to Miles using 1.60934
B10: If your vehicle is not listed please contact info@sustainquality.co.uk
B12: Business Travel | D12: KM | K12: MILES TO KM | M12: MILES
K13: 1.60934
A14: Business Travel (SCOPE 3) | B14: Car (small) | Petrol | D14: =$K$13*M14 -> 0 | E14: =$K$13*N14 -> 0 | F14: =$K$13*O14 -> 0 | G14: =$K$13*P14 -> 0 | H14: =$K$13*Q14 -> 0
B15: Car (medium) | Petrol | D15: =$K$13*M15 -> 0 | E15: =$K$13*N15 -> 0 | F15: =$K$13*O15 -> 0 | G15: =$K$13*P15 -> 0 | H15: =$K$13*Q15 -> 0
B16: Car (large) | Petrol | D16: =$K$13*M16 -> 0 | E16: =$K$13*N16 -> 0 | F16: =$K$13*O16 -> 0 | G16: =$K$13*P16 -> 0 | H16: =$K$13*Q16 -> 0
B17: Car (average) | Petrol | D17: =$K$13*M17 -> 0 | E17: =$K$13*N17 -> 0 | F17: =$K$13*O17 -> 0 | G17: =$K$13*P17 -> 0 | H17: =$K$13*Q17 -> 0
B18: Car (small) | Diesel | D18: =$K$13*M18 -> 0 | E18: =$K$13*N18 -> 0 | F18: =$K$13*O18 -> 0 | G18: =$K$13*P18 -> 0 | H18: =$K$13*Q18 -> 0
B19: Car (medium) | Diesel | D19: =$K$13*M19 -> 0 | E19: =$K$13*N19 -> 0 | F19: =$K$13*O19 -> 0 | G19: =$K$13*P19 -> 0 | H19: =$K$13*Q19 -> 0
B20: Car (large) | Diesel | D20: =$K$13*M20 -> 0 | E20: =$K$13*N20 -> 0 | F20: =$K$13*O20 -> 0 | G20: =$K$13*P20 -> 0 | H20: =$K$13*Q20 -> 0
B21: Car (average) | Diesel | D21: =$K$13*M21 -> 0 | E21: =$K$13*N21 -> 0 | F21: =$K$13*O21 -> 0 | G21: =$K$13*P21 -> 0 | H21: =$K$13*Q21 -> 0
B22: Car (small) | Hybrid | D22: =$K$13*M22 -> 0 | E22: =$K$13*N22 -> 0 | F22: =$K$13*O22 -> 0 | G22: =$K$13*P22 -> 0 | H22: =$K$13*Q22 -> 0
B23: Car (medium) | Hybrid | D23: =$K$13*M23 -> 0 | E23: =$K$13*N23 -> 0 | F23: =$K$13*O23 -> 0 | G23: =$K$13*P23 -> 0 | H23: =$K$13*Q23 -> 0
B24: Car (large) | Hybrid | D24: =$K$13*M24 -> 0 | E24: =$K$13*N24 -> 0 | F24: =$K$13*O24 -> 0 | G24: =$K$13*P24 -> 0 | H24: =$K$13*Q24 -> 0
B25: Car (average) | Hybrid | D25: =$K$13*M25 -> 0 | E25: =$K$13*N25 -> 0 | F25: =$K$13*O25 -> 0 | G25: =$K$13*P25 -> 0 | H25: =$K$13*Q25 -> 0
B26: Car (small) | Plug-in Hybrid | D26: =$K$13*M26 -> 0 | E26: =$K$13*N26 -> 0 | F26: =$K$13*O26 -> 0 | G26: =$K$13*P26 -> 0 | H26: =$K$13*Q26 -> 0
... B53: International (to/from non-UK) - business class | D53: =$K$13*M53 -> 0 | E53: =$K$13*N53 -> 0 | F53: =$K$13*O53 -> 0 | G53: =$K$13*P53 -> 0 | H53: =$K$13*Q53 -> 0
A54: Freighting goods (SCOPE 3) | B54: Average Van (up to 3.5 tonnes) (diesel) | D54: =$K$13*M54 -> 0 | E54: =$K$13*N54 -> 0 | F54: =$K$13*O54 -> 0 | G54: =$K$13*P54 -> 0 | H54: =$K$13*Q54 -> 0
B55: Average Van (up to 3.5 tonnes) (petrol) | D55: =$K$13*M55 -> 0 | E55: =$K$13*N55 -> 0 | F55: =$K$13*O55 -> 0 | G55: =$K$13*P55 -> 0 | H55: =$K$13*Q55 -> 0
B56: HGVs (diesel) | D56: =$K$13*M56 -> 0 | E56: =$K$13*N56 -> 0 | F56: =$K$13*O56 -> 0 | G56: =$K$13*P56 -> 0 | H56: =$K$13*Q56 -> 0
B57: Refrigerated HGVs (diesel) | D57: =$K$13*M57 -> 0 | E57: =$K$13*N57 -> 0 | F57: =$K$13*O57 -> 0 | G57: =$K$13*P57 -> 0 | H57: =$K$13*Q57 -> 0
B58: Freight flights (Domestic to/from UK) | D58: =$K$13*M58 -> 0 | E58: =$K$13*N58 -> 0 | F58: =$K$13*O58 -> 0 | G58: =$K$13*P58 -> 0 | H58: =$K$13*Q58 -> 0
B59: Freight flights (Short-haul to/from UK) | D59: =$K$13*M59 -> 0 | E59: =$K$13*N59 -> 0 | F59: =$K$13*O59 -> 0 | G59: =$K$13*P59 -> 0 | H59: =$K$13*Q59 -> 0
B60: Freight flights (Long haul to/from UK) | D60: =$K$13*M60 -> 0 | E60: =$K$13*N60 -> 0 | F60: =$K$13*O60 -> 0 | G60: =$K$13*P60 -> 0 | H60: =$K$13*Q60 -> 0
B61: Freight flights (International to/from UK) | D61: =$K$13*M61 -> 0 | E61: =$K$13*N61 -> 0 | F61: =$K$13*O61 -> 0 | G61: =$K$13*P61 -> 0 | H61: =$K$13*Q61 -> 0
B62: Rail (freight train) | D62: =$K$13*M62 -> 0 | E62: =$K$13*N62 -> 0 | F62: =$K$13*O62 -> 0 | G62: =$K$13*P62 -> 0 | H62: =$K$13*Q62 -> 0
B63: Cargo Ship (Bulk carrier) | D63: =$K$13*M63 -> 0 | E63: =$K$13*N63 -> 0 | F63: =$K$13*O63 -> 0 | G63: =$K$13*P63 -> 0 | H63: =$K$13*Q63 -> 0
B64: Cargo Ship (General cargo) | D64: =$K$13*M64 -> 0 | E64: =$K$13*N64 -> 0 | F64: =$K$13*O64 -> 0 | G64: =$K$13*P64 -> 0 | H64: =$K$13*Q64 -> 0
B65: Cargo Ship (Container ship) | D65: =$K$13*M65 -> 0 | E65: =$K$13*N65 -> 0 | F65: =$K$13*O65 -> 0 | G65: =$K$13*P65 -> 0 | H65: =$K$13*Q65 -> 0
B66: Cargo Ship (Vehicle transport) | D66: =$K$13*M66 -> 0 | E66: =$K$13*N66 -> 0 | F66: =$K$13*O66 -> 0 | G66: =$K$13*P66 -> 0 | H66: =$K$13*Q66 -> 0
B67: Cargo Ship (Refrigerated cargo) | D67: =$K$13*M67 -> 0 | E67: =$K$13*N67 -> 0 | F67: =$K$13*O67 -> 0 | G67: =$K$13*P67 -> 0 | H67: =$K$13*Q67 -> 0
A68: Staff Commute (SCOPE 3) | B68: Car (small) | Petrol | D68: =$K$13*M68 -> 0 | E68: =$K$13*N68 -> 0 | F68: =$K$13*O68 -> 0 | G68: =$K$13*P68 -> 0 | H68: =$K$13*Q68 -> 0
...

Sheet Refrigerants
A1: REFRIGERANTS
A2: Top ups made to air conditioning units - Many refrigeration, fire protection and air conditioning equipment contain a type of F gas (Fluorinated greenhouse gas), which has a large carbon footprint. Please include the type and quantity of top up that has been done during the reporting year. You can find this information in the service sheets provided by your air conditioning or refrigeration contractor
C4: Two options (19 - Calendar or 19 - Financial
A5: Period | C5: April 2019 - March 2020 | D5: April 2020 - March 2021 | E5: April 2021 - March 2022 | F5: April 2022 - March 2023 | G5: April 2023 - March 2024 | H5: April 2024 - March 2025 | I5: financial year/ full year - specify the months of data provided
A6: Data Input | C6: Two options (Montly or Annual) - Is it applicable?
A8: R404A
A10: R404A | I10: Kg
A12: Notes
A14: R407A
A16: R407A | I16: Kg
A18: Notes
A20: R407C
A22: R407C | I22: Kg
A24: Notes
A26: R408A
A28: R408A | I28: Kg
A30: Notes
A33: R410A
A35: R410A | I35: Kg
A37: Notes
A40: R134a
A42: R134a | I42: Kg
A44: Notes
A48: Other Refrigerant:
A50: Emission Type 1
A52: Notes
A54: Emission Factor
A58: Attach files
A59: Please attach Refrigerant charge receipts/spreadsheets/reports (a sample including the first and the last bill during the period
A63: CLICK HERE TO SUBMIT FOR REVIEW

Sheet Hotel Stay
A1: Hotel Stay
C2: Two options (19 - Calendar or 19 - Financial
A3: Period | C3: April 2019 - March 2020 | D3: April 2020 - March 2021 | E3: April 2021 - March 2022 | F3: April 2022 - March 2023 | G3: April 2023 - March 2024 | H3: April 2024 - March 2025 | I3: financial year/ full year - specify the months of data provided
A4: Data Input | C4: Two options (Montly or Annual)
C6: CONSUMPTION | D6: CONSUMPTION | E6: CONSUMPTION | F6: CONSUMPTION | G6: CONSUMPTION
A7: Hotel Stay UK | I7: nights
A8: Hotel Stay London | I8: nights
A11: Hotel Notes | J11: Please add notes related to Hotel data sources and assumptions
A14: Custom Emissions
A15: Description - if other country | I15: Emissions (kg CO2e) | K15: If you have calculated your emissions elswhere, please include them here.
A18: Attach files
A19: Please attach hotel receipts/spreadsheets/reports (a sample including the first and the last bill during the period
A23: CLICK HERE TO SUBMIT FOR REVIEW
A25: If monthly
A26: If Finacial Year
A27: Montly Input | B27: April | C27: May | D27: June | E27: July | F27: August | G27: September | H27: October | I27: November | J27: December | K27: January | L27: February | M27: March | N27: Total
A28: Hotel Stay UK | N28: =SUM(B28:M28) -> 0
A29: Hotel Stay London | N29: =SUM(B29:M29) -> 0
A31: If Calendar Year
A32: Montly Input | B32: January | C32: February | D32: March | E32: April | F32: May | G32: June | H32: July | I32: August | J32: September | K32: October | L32: November | M32: December | N32: Total
A33: Hotel Stay UK | N33: =SUM(B33:M33) -> 0
A34: Hotel Stay London | N34: =SUM(B34:M34) -> 0

Sheet Working from Home
A1: Working from Home
C2: Two options (19 - Calendar or 19 - Financial
A3: Period | C3: April 2019 - March 2020 | D3: April 2020 - March 2021 | E3: April 2021 - March 2022 | F3: April 2022 - March 2023 | G3: April 2023 - March 2024 | H3: April 2024 - March 2025 | I3: financial year/ full year - specify the months of data provided
A4: Actual/FTE | C4: Confirm if hours are actual or FTE
A5: Data Input | C5: Two options (Montly or Annual)
C6: CONSUMPTION | D6: CONSUMPTION | E6: CONSUMPTION | F6: CONSUMPTION | G6: CONSUMPTION
A7: Working from home | G7: 4179.6 | I7: working hours
A10: Working from home Notes | J10: Please add notes related to working from home data sources and assumptions
A13: Custom Emissions
A14: Description | I14: Emissions (kg CO2e) | K14: If you have calculated your emissions elswhere, please include them here.
A17: Attach files
A18: Please attach receipts/spreadsheets/reports (a sample including the first and the last bill during the period
A24: CLICK HERE TO SUBMIT FOR REVIEW
A26: If monthly
A27: If Finacial Year
A28: Montly Input | B28: April | C28: May | D28: June | E28: July | F28: August | G28: September | H28: October | I28: November | J28: December | K28: January | L28: February | M28: March | N28: Total
A29: Working from home | N29: =SUM(B29:M29) -> 0
A31: If Calendar Year
A32: Montly Input | B32: January | C32: February | D32: March | E32: April | F32: May | G32: June | H32: July | I32: August | J32: September | K32: October | L32: November | M32: December | N32: Total
A33: Working from home | N33: =SUM(B33:M33) -> 0

Sheet Material Use
A1: Material Use
C2: Two options (19 - Calendar or 19 - Financial
A3: Period | C3: April 2019 - March 2020 | D3: April 2020 - March 2021 | E3: April 2021 - March 2022 | F3: April 2022 - March 2023 | G3: April 2023 - March 2024 | H3: April 2024 - March 2025 | I3: financial year/ full year - specify the months of data provided
A5: Please complete the data in Tonnes and remove the 0. If your data is in KG, please complete the column KG and the calculator will convert KG to Tonnes /1000
A6: If your vehicle is not listed please contact info@sustainquality.co.uk
C8: Tonnes | J8: KG to Tonnes | L8: KG
A9: Average construction (primary material production)
A10: Aggregates (primary material production)
A11: Aggregates (re-used)
A12: Aggregates (closed-loop)
A13: Asphalt (primary material production)
A14: Asphalt (re-used)
A15: Asphalt (closed-loop)
A16: Bricks (primary material production)
A17: Concrete (primary material production)
A18: Concrete (closed-loop)
A19: Other?
A23: Materials Notes | J23: Please add notes related to Material data sources and assumptions
A26: Custom Emissions
A27: Description | I27: Emissions (kg CO2e) | K27: If you have calculated your emissions elswhere, please include them here.
A30: Attach files
A31: Please attach materials EPD/ISO certificates/delivery note/receipts/spreadsheets/reports (a sample including the first and the last bill during the period
A37: CLICK HERE TO SUBMIT FOR REVIEW

Sheet Elements Tab Energy...
B3: The same tab for all elements
B4: Energy | C4: Water | D4: Waste | E4: Business and Staff tavel | G4: refrigerants | H4: Hotel Stay | I4: Working from Home

Sheet Carbon Reduction Plan
A1: Notes
A2: Please use column F to write the strategies / plans for the next years that may reduce the carbon emissions - for example ASHP, PV panels, off set, lighting….as per CRP template
A3: Please input the estimated % reduction for each year - column D
A5: Completed Carbon Reduction initiatives
A6: [Instructions:
A7: Briefly provide details of some of your completed carbon reduction projects. This is for information only.
A8: This may include environmental management measures such as certification schemes like ISO14001 or PAS 2060, signing up to SBTI or specific measures you have taken such as; the adoption of LED/PIR lighting controls, changes to policy resulting in a reduction in company travel and flights or the electrification of the company fleet.]
A10: Future (Planned) Carbon Reduction Initiatives
A11: Instructions: Briefly provide details of some of any likely/proposed future carbon reduction projects. This is for information only.]
A15: CARBON REDUCTION PLAN
B16: Years | C16: Current Emissions | D16: Reduction (%) | E16: Future Emissions | F16: Carbon Reduction Measures (Incl Scope 1,2,3) | H16: Notes | J16: References
B17: 2020 | C17: FROM CALCS | D17: - | H17: Completed Actions
B18: 2021 | C18: FROM CALCS | D18: =C18/C17 -> #VALUE! | H18: Completed Actions
B19: 2022 | C19: FROM CALCS | D19: =C19/C18 -> #VALUE! | H19: Completed Actions
B20: 2022/2023 | C20: ='2024 Results Graphs'!E84 -> 0 | D20: 0.5 | E20: =C20-C20*D20 -> 0 | H20: Data input - refer to Results
B21: 2030 | C21: =E20 -> 0 | D21: 0.3 | E21: =C21-C21*D21 -> 0 | H21: 50% reduction? - UK target | J21: The UK has set the most ambitious target to reduce carbon emissions by 68% by 2030 compared to 1990 levels – and is the only major economy to have set a target of 77% for 2035
B22: 2031 | C22: =E21 -> 0 | D22: 0.3 | E22: =C22-C22*D22 -> 0 | J22: https://www.gov.uk/government/news/pm-recommits-uk-to-net-zero-by-2050-and-pledges-a-fairer-path-to-achieving-target-to-ease-the-financial-burden-on-british-families#:~:text=The%20UK%20has%20set%20the,target%20of%2077%25%20for%202035.
B23: 2032 | C23: =E22 -> 0 | D23: 0.3 | E23: =C23-C23*D23 -> 0
B24: 2033 | C24: =E23 -> 0 | D24: 0.3 | E24: =C24-C24*D24 -> 0
B25: 2034 | C25: =E24 -> 0 | D25: 0.3 | E25: =C25-C25*D25 -> 0
B26: 2035 | C26: =E25 -> 0 | D26: 0.3 | E26: =C26-C26*D26 -> 0
B27: 2036 | C27: =E26 -> 0 | D27: 0.3 | E27: =C27-C27*D27 -> 0
B28: 2037 | C28: =E27 -> 0 | D28: 0.3 | E28: =C28-C28*D28 -> 0
B29: 2038 | C29: =E28 -> 0 | D29: 0.3 | E29: =C29-C29*D29 -> 0
B30: 2040 | C30: =E29 -> 0 | D30: 0.3 | E30: =C30-C30*D30 -> 0
B31: 2041 | C31: =E30 -> 0 | D31: 0.3 | E31: =C31-C31*D31 -> 0
B32: 2042 | C32: =E31 -> 0 | D32: 0.3 | E32: =C32-C32*D32 -> 0
B33: 2043 | C33: =E32 -> 0 | D33: 0.3 | E33: =C33-C33*D33 -> 0
B34: 2044 | C34: =E33 -> 0 | D34: 0.3 | E34: =C34-C34*D34 -> 0
... B39: 2049 | C39: =E38 -> 0 | D39: 0.3 | E39: =C39-C39*D39 -> 0
B40: 2050 | C40: =E39 -> 0 | D40: 0.3 | E40: =C40-C40*D40 -> 0 | H40: Net Zero | J40: https://www.gov.uk/government/news/pm-recommits-uk-to-net-zero-by-2050-and-pledges-a-fairer-path-to-achieving-target-to-ease-the-financial-burden-on-british-families#:~:text=The%20UK%20has%20set%20the,target%20of%2077%25%20for%202035.
B61: NOTES FOR REPORT
A69: Attach files
A70: Please attach delivery note/receipts/spreadsheets/reports (a sample including the first and the last bill during the period
A78: CLICK HERE TO SUBMIT FOR REVIEW

Sheet BREEAM IN USE Part 2
A1: BIU tracker | B1: 0
A3: Part 2 - Management Performance
A5: Management
A6: Credit issue | B6: Credit name | C6: Question | E6: Credits Available | F6: Answer (mark with a 'X') | G6: Download Template | H6: Attach file
A7: MAN01 | B7: Building user guide | C7: Has relevant information from the building user guide been made accessible to all buiding users? | D7: A- not answered | E7: 0
D8: B- YES | E8: 0
D9: C - NO | E9: 2 | G9: Link to template
A10: MAN02 | B10: Management engagement and feedback | C10: What processes are in place to ensure good communication between building managers, building users, and neighbours? | D10: A - not answered | E10: 0
D11: B - Formal communication between building management and building users | E11: 1
D12: C - Regular meetings between building management and building users | E12: 2
D13: D - Building users are provided with information relating to environmental policies and performance of the asset | E13: 1
D14: E - Proactive engagement with neighbours and community, including a procedure that deals with any complaints relating to the asset and associated operations | E14: 1
D15: F - Occupant satisfaction surveyrs conducted by building management | E15: 2
D16: G - Occupant satisfaction surveys conducted by a third party | E16: 4
A17: MAN03 | B17: Maintenance policies and procedures | C17: Which of the following maintenace policies and procedures are in place? | D17: A - not answered | E17: 0
D18: B - A full set of operations and maintencance (O&M) manuals available and accessible by building management/facilities management staff | E18: 1
D19: C - a proactive maintenance policy/procedure for the external site | E19: 2
D20: D - a proactive maintenance policy/procedure for the building fabric | E20: 2
D21: E - a proactive maintenance policy/procedure for heating, ventilation and cooling (HVAC) sustems, as applicable, and hot water | E21: 2
D22: F - a proactive maintenance policy/procedure for lighting | E22: 2
D23: G - Regular review of the Building Management Systems by suitably qualified staff from the in-house Facilities Management team | E23: 2
D24: H - Regular review of the Building Management System by an accredited third party auditor | E24: 4
A25: MAN04 | B25: Environmental policies and procedures | C25: Has an environmental policy or plan been developed by the building management organisation? | D25: A- not answered | E25: 0
D26: B - the building management organisation has developed and implemented an environmental policy or plan | E26: 2 | G26: Link to template
D27: C - The environmental management policy or plan has been accredited to ISO 14001 or equivalent standards | E27: 2
D28: D - Improvement targets have been set for energy, water and waste/recycling | E28: 2 | G28: Link to template
D29: E - The environmental management policy or plan addresses resilience and climate risks | E29: Exemplary | G29: Link to template
A30: MAN05 | B30: Green lease | C30: Are green lease agreements/contracts with tenants in place? | D30: A - not answered | E30: 0
D31: B - no | E31: 0
D32: C - Yes for >25% of tenants, including sharing of environmental performance data | E32: 1
D33: D - Yes for >25% of tenants, including sharing of environmental performance data and targets for Energy, and Water or Waste reduction | E33: 2
D34: E - Yes for >50% of tenants, including sharing of environmental performance data | E34: 2
D35: F - Yes for >50% of tenants, including sharing of environmental performance data and targets for Energy, and Water use or Waste reduction | E35: 3
D36: G - E - Yes for >75% of tenants, including sharing of environmental performance data | E36: 3
D37: H - Yes for >75% of tenants, including sharing of environmental performance data and targets for Energy, and Water use or Waste reduction | E37: 4
A40: Health and Wellbeing
A41: Credit issue | B41: Credit name | C41: Question | E41: Credits Available | F41: Answer (mark with a 'X')
A42: HEA14 | B42: Thermal Comfort | C42: Is the thermal comfort of asset users in occupied spaces regularly monitored? | D42: A - not answered | E42: 0
D43: B - No | E43: 0
D44: C - Yes, through temperature measurement | E44: 2
...

Sheet Eco Audit action plan
A4: Date of the Eco Audit
A5: Name of the Eco Auditor
A9: Priority | B9: Further Action | C9: Cost Implication | D9: Impact | E9: SDG | F9: Date | G9: Progress
A10: Environmental and Procurement Policy
A11: Short Term | B11: Develop the Environmental Policy in full and ensure it is reviewed annually. | C11: £ | D11: High
A12: Short Term | B12: Communicate to the public on any outcomes/improvements in sustainability practices, on the website or in annual reports. | C12: £ | D12: Low
A13: Ongoing | B13: Appoint a dedicated individual to oversee ethical purchases and purchase certified items. | C13: ££ | D13: Medium
A15: Energy
A16: Ongoing | B16: Monitor energy consumption in the form of a spreadsheet or through bills. | C16: £ | D16: High
A17: Medium Term | B17: Replace single-glazed windows with double-glazed windows. | C17: ££££ | D17: Low
A18: Medium Term | B18: Integrate PIR systems on all appropriate lights. | C18: ££££ | D18: Medium
A19: Medium Term | B19: Replace all lights with LED bulbs. | C19: £££ | D19: High
A20: Short Term | B20: Carry out pre-feasibility studies for solar panels. | C20: £ | D20: Low
A21: Waste
A22: Ongoing | B22: Monitor the waste generation of the charity consistently and accurately. | C22: £ | D22: High
A23: Short Term | B23: Place recycling bins in all spaces. | C23: ££ | D23: Low
A24: Short Term | B24: Increase labelling of waste bins. | C24: £ | D24: Medium
A25: Water
A26: Long Term | B26: Ensure that all water appliances throughout all buildings are water efficient. | C26: £ | D26: High
A27: Ongoing | B27: Consider starting to monitor water consumption and wastewater through online spreadsheets. | C27: £ | D27: Low
A28: Health and Wellbeing
A29: Medium Term | B29: Increase indoor plants throughout all spaces. | C29: ££ | D29: High
A30: Short Term | B30: Investigate the addition of a green roof. | C30: £ | D30: Low
A31: Medium Term | B31: Implement Circadian lighting in the appropriate areas. | C31: £££ | D31: High
A32: Travel
A33: Medium Term | B33: Install bicycle storage. | C33: ££ | D33: High
A34: Short Term | B34: Carry out a travel survey to have a better understanding of how staff and visitors travel to the centre. | C34: £ | D34: Low
A35: ADD TAILOR MADE SECTION FOR SPECIFIC ORGANISATION
A37: to include the cost implication (we may need explain £, ££, £££, ££££, £££££)
A38: to include the SDG for each section
A41: CLICK HERE TO SUBMIT FOR REVIEW

Sheet Offset - live projects
A2: Offset
A4: Based on the available data, this report assesses the total emissions of
A6: ='1x2 Carbon Emissions KgCO2e SQ'!H197 -> 0 | B6: tonnes of CO2e. during the period of
A7: ='1x2 Carbon Emissions KgCO2e SQ'!H193 -> 2023
A9: The emissions can be offset through chossing one of the proposed strategies below to achieve Carbon Neutrality.
A13: Projects to Offset
A15: Verified Carbon Standard (VCS)
A17: The Verified Carbon Standard (VCS) is an offset certification program managed by Verra. It is a widely supported, with projects worldwide. VCS is focused wholly on removing and reducing greenhouse gas (GHG) emissions, and there are strict guidelines that projects have to meet to be verified under the VCS program.
A19: The VCS issues a Voluntary Carbon Unit (VCU) to approved programs, and an awarded VCU represents the removal or reduction of one tonne of GHG emissions. These VCUs are what we purchase on the global carbon market and allocate to you when you purchase a carbon offset.
A21: The basic criteria for an approved project include:
A22: Real: all GHG emission reduction or removal by the project must be proven to have genuinely taken place.
A23: Measurable: emissions reductions or removal must be measured and quantified using accurate measurement methods against a credibly established baseline.
A24: Additional: all GHG removals and reductions should be over an established baseline to ensure that any removals or reductions are because of the project being in place.
A25: Conservative: in case of any uncertainty in measurement, lower values will be recorded and used to ensure there is no over-estimation of VCUs.
A26: Independently audited: an accredited team with experience in the relevant field and country needs to verify all GHG emission reductions and removals.
A27: Transparent: all data collected and recorded should be appropriately disclosed to the public so that users can make informed decisions with confidence. This information about each project is available in the Verra Project registry, along with a list of all VCS certified projects.
... A32: Potential offset project from Verified Carbon Standard (VCS):
A34: Project name | B34: Housing Decarbonisation in the UK | C34: OPTION 2 Housing Decarbonisation in the UK | D34: OPTION 3 Housing Decarbonisation in the UK
A35: Project description | B35: This project facilitates the decarbonisation of housing stock in the United Kingdom. Emission reductions are generated by reductions in fossil fuel consumption in dwellings that are decarbonised compared to baseline consumption. The aggregated emissions from fossil fuel consumption of dwellings in the United Kingdom make up a significant component of greenhouse gas emissions; they also pose a significant opportunity to reduce real emissions. | C35: This project facilitates the decarbonisation of housing stock in the United Kingdom. Emission reductions are generated by reductions in fossil fuel consumption in dwellings that are decarbonised compared to baseline consumption. The aggregated emissions from fossil fuel consumption of dwellings in the United Kingdom make up a significant component of greenhouse gas emissions; they also pose a significant opportunity to reduce real emissions. | D35: This project facilitates the decarbonisation of housing stock in the United Kingdom. Emission reductions are generated by reductions in fossil fuel consumption in dwellings that are decarbonised compared to baseline consumption. The aggregated emissions from fossil fuel consumption of dwellings in the United Kingdom make up a significant component of greenhouse gas emissions; they also pose a significant opportunity to reduce real emissions.
A36: Link | B36: https://registry.verra.org/app/projectDetail/VCS/2649 | C36: https://registry.verra.org/app/projectDetail/VCS/2649 | D36: https://registry.verra.org/app/projectDetail/VCS/2649
A38: Mark here your option
A41: Gold Standard Verified Reduction (VERs)
A43: The Gold Standard was developed in 2003 by the World Wide Fund for Nature (WWF). It is an international offset program administered by the Gold Standard Foundation based in Geneve, Switzerland. Compared to the VCS, the Gold Standard has additional requirements when certifying a project. The requirements for a Gold Standard certification are:
A44: The project should reduce or remove one of the three eligible GHGs: methane, carbon dioxide, and nitrous oxide. The measurement of this removal has similar criteria to that of the VCS outlined above.
A45: The project should be achieving its goal by supplying renewable energy, reducing end-user energy usage, afforestation, reforestation, or agriculture.
A46: The project should not be applying for another certification to prevent double counting.
A47: The additional GHC emission reduction or removal should be documented and should be occurring because of the project.
A48: The project should be contributing to at least three of the Sustainable Development Goals
A50: The final assessment criterium is particularly important. It means that in addition to reducing or removing GHG emissions, a Gold Standard certified project also benefits the local population’s financial, social, and environmental outcomes.
A52: Potential offset projects from Gold Standard Renewable Energy Projects (VERs) are presented below.
A54: Project name | B54: FPD Robotic E-Waste Recycling Project | C54: 30 MW Wind Power Project at Surajbari, Guajarat in India | D54: BK Energia Itacoatiara Project
A55: Project description | B55: FPD will work locally in the collection of E-waste and segregate them through an automated robotic arm developed by FPD. After segregation, the components are then processed to separate metals and plastics which are used as replacements for virgin materials in new production units. This project is implemented in the host country-United Kingdom. | C55: The proposed project activity comprises of installation and operation of fifty (50) numbers of 600 kW Wind Electricity Generators (WEGs) having a combined wind power generation capacity of 30 MW at Surajbari creek covering Chandrodi, Khodasar, Rajasthali and Naransari villages of Kutch district in Gujarat state, India. The annual estimated energy generation out of the project activity is about 60,444 MWh. | D55: The project generates electricity with a thermoelectric power plant (see picture below) using wood waste from an FSC1-certified forest and a wood processing company in the city of Itacoatiara, in the State of Amazonas, Brazil. The electricity is generated with a high-pressure boiler (42 bar – 420° C) and a multiple-stage condensing steam turbine coupled with a 9 MWelt generator.
A57: Link | B57: https://registry.goldstandard.org/projects/details/3584 | C57: https://registry.goldstandard.org/projects/details/2603 | D57: https://registry.goldstandard.org/projects/details/1181
A60: Please Mark here your option
A65: Carbon Neutrality
A66: Carbon neutrality means having a balance between emitting carbon and absorbing carbon from the atmosphere in carbon sinks. Removing carbon oxide from the atmosphere and then storing it is known as carbon sequestration. In order to achieve net zero emissions, all worldwide greenhouse gas (GHG) emissions will have to be counterbalanced by carbon sequestration.
A68: Carbon sink is any system that absorbs more carbon than it emits. The main natural carbon sinks are soil, forests and oceans. According to estimates, natural sinks remove between 9.5 and 11 Gt of CO2 per year. Annual global CO2 emissions reached 36.0 Gt in 2020.
A70: To date, no artificial carbon sinks are able to remove carbon from the atmosphere on the necessary scale to fight global warming.
A72: The carbon stored in natural sinks such as forests is released into the atmosphere through forest fires, changes in land use or logging. This is why it is essential to reduce carbon emissions in order to reach climate neutrality.

Sheet 2024 Results Graphs
A4: Calculation | B4: 2024
B7: SCOPE 1 | D7: SCOPE 2 | F7: SCOPE 3
A8: KG CO2e | B8: =F81 -> 0 | D8: =F82 -> 0 | F8: =F83 -> 1395.0719
B25: 2024
B26: Energy | C26: Water | D26: Waste | E26: Transport | F26: Refrigerants | G26: Home Working | H26: Hotel Stay (UK) | I26: Materials Use
B27: =F52 -> 0 | C27: =F53 -> 0 | D27: =F54 -> 0 | E27: =F55 -> 0 | F27: =F56 -> 0 | G27: =F57 -> 1395.0719 | H27: =F58 -> 0 | I27: =F59 -> 0
B42: 2024 Renewable energy Generation
B43: ='1x2 Carbon Emissions KgCO2e SQ'!I10 -> 0 | C43: KG CO2e saved
A49: Annual summary KG of CO2e
B51: 2020 | C51: 2021 | D51: 2022 | E51: 2023 | F51: 2024
A52: Energy | B52: ='1x2 Carbon Emissions KgCO2e SQ'!E183 -> 0 | C52: ='1x2 Carbon Emissions KgCO2e SQ'!F183 -> 0 | D52: ='1x2 Carbon Emissions KgCO2e SQ'!G183 -> 0 | E52: ='1x2 Carbon Emissions KgCO2e SQ'!H183 -> 0 | F52: ='1x2 Carbon Emissions KgCO2e SQ'!I183 -> 0
A53: Water | B53: ='1x2 Carbon Emissions KgCO2e SQ'!E184 -> 0 | C53: ='1x2 Carbon Emissions KgCO2e SQ'!F184 -> 0 | D53: ='1x2 Carbon Emissions KgCO2e SQ'!G184 -> 0 | E53: ='1x2 Carbon Emissions KgCO2e SQ'!H184 -> 0 | F53: ='1x2 Carbon Emissions KgCO2e SQ'!I184 -> 0
A54: Waste | B54: ='1x2 Carbon Emissions KgCO2e SQ'!E185 -> 0 | C54: ='1x2 Carbon Emissions KgCO2e SQ'!F185 -> 0 | D54: ='1x2 Carbon Emissions KgCO2e SQ'!G185 -> 0 | E54: ='1x2 Carbon Emissions KgCO2e SQ'!H185 -> 0 | F54: ='1x2 Carbon Emissions KgCO2e SQ'!I185 -> 0
A55: Transport | B55: ='1x2 Carbon Emissions KgCO2e SQ'!E186 -> 0 | C55: ='1x2 Carbon Emissions KgCO2e SQ'!F186 -> 0 | D55: ='1x2 Carbon Emissions KgCO2e SQ'!G186 -> 0 | E55: ='1x2 Carbon Emissions KgCO2e SQ'!H186 -> 0 | F55: ='1x2 Carbon Emissions KgCO2e SQ'!I186 -> 0
A56: Refrigerants | B56: ='1x2 Carbon Emissions KgCO2e SQ'!E187 -> 0 | C56: ='1x2 Carbon Emissions KgCO2e SQ'!F187 -> 0 | D56: ='1x2 Carbon Emissions KgCO2e SQ'!G187 -> 0 | E56: ='1x2 Carbon Emissions KgCO2e SQ'!H187 -> 0 | F56: ='1x2 Carbon Emissions KgCO2e SQ'!I187 -> 0
A57: Home Working | B57: ='1x2 Carbon Emissions KgCO2e SQ'!E188 -> 0 | C57: ='1x2 Carbon Emissions KgCO2e SQ'!F188 -> 0 | D57: ='1x2 Carbon Emissions KgCO2e SQ'!G188 -> 0 | E57: ='1x2 Carbon Emissions KgCO2e SQ'!H188 -> 0 | F57: ='1x2 Carbon Emissions KgCO2e SQ'!I188 -> 1395.0719
A58: Hotel Stay (UK) | B58: ='1x2 Carbon Emissions KgCO2e SQ'!E189 -> 0 | C58: ='1x2 Carbon Emissions KgCO2e SQ'!F189 -> 0 | D58: ='1x2 Carbon Emissions KgCO2e SQ'!G189 -> 0 | E58: ='1x2 Carbon Emissions KgCO2e SQ'!H189 -> 0 | F58: ='1x2 Carbon Emissions KgCO2e SQ'!I189 -> 0
A59: Materials Use | B59: ='1x2 Carbon Emissions KgCO2e SQ'!E190 -> 0 | C59: ='1x2 Carbon Emissions KgCO2e SQ'!F190 -> 0 | D59: ='1x2 Carbon Emissions KgCO2e SQ'!G190 -> 0 | E59: ='1x2 Carbon Emissions KgCO2e SQ'!H190 -> 0 | F59: ='1x2 Carbon Emissions KgCO2e SQ'!I190 -> 0
A60: Total | B60: =SUM(B52:B59) -> 0 | C60: =SUM(C52:C59) -> 0 | D60: =SUM(D52:D59) -> 0 | E60: =SUM(E52:E59) -> 0 | F60: =SUM(F52:F59) -> 1395.0719
A80: Carbon Emissions Scope Summary | B80: 2020 | C80: 2021 | D80: 2022 | E80: 2023 | F80: 2024
A81: Scope 1 | B81: ='1x2 Carbon Emissions KgCO2e SQ'!E194 -> 0 | C81: ='1x2 Carbon Emissions KgCO2e SQ'!F194 -> 0 | D81: ='1x2 Carbon Emissions KgCO2e SQ'!G194 -> 0 | E81: ='1x2 Carbon Emissions KgCO2e SQ'!H194 -> 0 | F81: ='1x2 Carbon Emissions KgCO2e SQ'!I194 -> 0
A82: Scope 2 | B82: ='1x2 Carbon Emissions KgCO2e SQ'!E195 -> 0 | C82: ='1x2 Carbon Emissions KgCO2e SQ'!F195 -> 0 | D82: ='1x2 Carbon Emissions KgCO2e SQ'!G195 -> 0 | E82: ='1x2 Carbon Emissions KgCO2e SQ'!H195 -> 0 | F82: ='1x2 Carbon Emissions KgCO2e SQ'!I195 -> 0
A83: Scope 3 | B83: ='1x2 Carbon Emissions KgCO2e SQ'!E196 -> 0 | C83: ='1x2 Carbon Emissions KgCO2e SQ'!F196 -> 0 | D83: ='1x2 Carbon Emissions KgCO2e SQ'!G196 -> 0 | E83: ='1x2 Carbon Emissions KgCO2e SQ'!H196 -> 0 | F83: ='1x2 Carbon Emissions KgCO2e SQ'!I196 -> 1395.0719
A84: Total | B84: =SUM(B81:B83) -> 0 | C84: =SUM(C81:C83) -> 0 | D84: =SUM(D81:D83) -> 0 | E84: =SUM(E81:E83) -> 0 | F84: =SUM(F81:F83) -> 1395.0719
A102: GRI Carbon Emission Criteria Confirmation for Scope 1, Scope 2 and Scope 3
A103: 2. Gases included in the calculation | B103: CO2e
A104: 3. Base year for the calculation, including: the rationale for choosing it; emissions in the base year; the context for any signficiant changes in emissions that triggered reculculations of base year emissions. | B104: ='Assessment Scope'!L20 -> 0
A105: 4. Source of emission factors. | B105: GOV UK
A106: 5. Standards, methodologies, assumptions, and/or calculation tools used. | B106: The GHG Protocol was used in consultation with the UK Government's Conversion Factors. The methodology was as follows: (1) Input data in relevant units; (2) Covert to all appropriate units (e.g., bags -> litre -> kilograms; miles -> kms); (3) Multiply the data by the UK Government's Conversion Factors. The sources of the Scottish Environmental Protection Agency were consulted to convert bags to litres to kilograms/
A110: 2024 Summary
A111: Scope | B111: Carbon Emission Source | C111: Input Data | D111: Input Data Unit | F111: Carbon Emissions (KgCO2e)
A112: 1 | B112: Natural gas used for company facilities | C112: ='2 Input data Summary SQ'!H4 -> 0 | D112: kWh | F112: ='1x2 Carbon Emissions KgCO2e SQ'!H4 -> 0
B113: Refrigerants | C113: =SUM('2 Input data Summary SQ'!H157:H163) -> 0 | D113: KG | F113: =SUM('1x2 Carbon Emissions KgCO2e SQ'!H157:H163) -> 0
B114: Company fleet & leased vehicles | C114: =SUM('2 Input data Summary SQ'!H127:H156) -> 0 | D114: Km | F114: =SUM('1x2 Carbon Emissions KgCO2e SQ'!H127:H156) -> 0
A115: 2 | B115: Electricity used for company facilities (incl. Transmission losses) | C115: ='2 Input data Summary SQ'!H3+'2 Input data Summary SQ'!H7 -> 0 | D115: kWh | F115: ='1x2 Carbon Emissions KgCO2e SQ'!H3+'1x2 Carbon Emissions KgCO2e SQ'!H7 -> 0
B116: Private vehicle for business use | C116: =SUM('2 Input data Summary SQ'!H111:H126) -> 0 | D116: Km | F116: =SUM('1x2 Carbon Emissions KgCO2e SQ'!H111:H126) -> 0
A117: 3 | B117: Business travel | C117: =SUM('2 Input data Summary SQ'!H17:H56) -> 0 | D117: Km | F117: =SUM('1x2 Carbon Emissions KgCO2e SQ'!H17:H56) -> 0
B118: Staff commute | C118: =SUM('1x2 Carbon Emissions KgCO2e SQ'!H71:H110) -> 0 | D118: Km | F118: =SUM('1x2 Carbon Emissions KgCO2e SQ'!H71:H110) -> 0
B119: Freighting goods | C119: =SUM('1x2 Carbon Emissions KgCO2e SQ'!H57:H70) -> 0 | D119: Km | F119: =SUM('1x2 Carbon Emissions KgCO2e SQ'!H57:H70) -> 0
B120: Water (consumption and wastewater) | C120: =SUM('2 Input data Summary SQ'!H11:H12) -> 0 | D120: M3 | F120: =SUM('1x2 Carbon Emissions KgCO2e SQ'!H11:H12) -> 0
...

Sheet Carbon Reduction Plan Report
A3: Carbon Reduction Plan
A4: This carbon Reduction Plan complies with the PPN0621 Carnon Reduction Plan
A6: Organisation name: | B6: ='General Info'!C14 -> 0
A7: Publication date:
A9: Commitment to achieving Net Zero
A10: =B6 -> 0 | B10: is committed to achieving Net Zero emissions by | F10: ='Assessment Scope'!C14 -> 0
A12: Baseline Emissions Footprint
A14: Baseline emissions are a record of the greenhouse gases that have been produced in the past and were produced prior to the introduction of any strategies to reduce emissions. Baseline emissions are the reference point against which emissions reduction can be measured.
A16: Baseline Year | B16: ='Assessment Scope'!C13 -> 0
A18: ='Assessment Scope'!D13 -> Add commentary regarding your Baseline Emissions as required: e.g. historic baseline which deviates from the requirements under this measure (e.g. no prior Scope 3 emissions reporting), where there is no previous reporting and the creation of a new baseline due to substantial organisational change or restructuring]
A20: Baseline Year Emissions
A21: Scope 1 | B21: Baseline year results on tab1x2 Carbon Emissions KgCO2e - Convert to Tonnes of CO2e
A22: Scope 2 | B22: Baseline year results on tab1x2 Carbon Emissions KgCO2e - Convert to Tonnes of CO2e
A23: Scope 3 (included sources) | B23: Baseline year results on tab1x2 Carbon Emissions KgCO2e - Convert to Tonnes of CO2e
A24: Total Emissions | B24: =SUM(B21:B23) -> 0 | C24: tCO2e
A26: Current Year Emissions
A27: Scope 1 | B27: Current (2023) year results on tab1x2 Carbon Emissions KgCO2e - Convert to Tonnes of CO2e
A28: Scope 2 | B28: Current (2023) year results on tab1x2 Carbon Emissions KgCO2e - Convert to Tonnes of CO2e
A29: Scope 3 (included sources) | B29: Current (2023) year results on tab1x2 Carbon Emissions KgCO2e - Convert to Tonnes of CO2e
A30: Total Emissions | B30: =SUM(B27:B29) -> 0 | C30: tCO2e
A33: Emissions reduction targets
A35: In order to continue our progress to achieving Net Zero, we have adopted the following carbon reduction targets.
A36: We project that carbon emissions will decrease over the next five years to | G36: tCO2e by
A37: =F10 -> 0 | B37: This is a reduction of | E37: %
A39: Progress against these targets can be seen in the graph below:
A42: GRAPH FROM CARBON EMISSIONS REDUCTION - NEEDS TO SHOW PROJECTED VS ACTUAL - EXAMPLE BELOW
A52: Carbon Reduction Projects
A54: Completed Carbon Reduction Initiatives
A55: The following environmental management measures and projects have been completed or implemented since the
A56: =B16 -> 0 | B56: baseline. The carbon emission reduction achieved by these schemes equate to
A57: XX | B57: tCO2e, a | C57: XX | D57: % reduction against the | F57: 20XX | G57: baseline
A58: and the measures will be in effect when performing the contract.
A61: Declaration and Sign Off
A62: This Carbon Reduction Plan has been completed in accordance with PPN 06/21 and associated guidance and reporting standard for Carbon Reduction Plans.
A63: Emissions have been reported and recorded in accordance with the published reporting standard for Carbon Reduction Plans and the GHG Reporting Protocol corporate standard[1] and uses the appropriate Government emission conversion factors for greenhouse gas company reporting[2].
A64: Scope 1 and Scope 2 emissions have been reported in accordance with SECR requirements, and the required subset of Scope 3 emissions have been reported in accordance with the published reporting standard for Carbon Reduction Plans and the Corporate Value Chain (Scope 3) Standard[3].
A65: This Carbon Reduction Plan has been reviewed and signed off by the board of directors (or equivalent management body).
A67: Signed on behalf of the Supplier:
A69: Signature
A71: Date
...

Sheet 1 Conversion Factor UK SQ
E1: Conv 2020 | F1: Conv 2021 | G1: Conv 2022 | H1: Conv 2023 | I1: Conv 2024
B2: Scope (1, 2, 3) | D2: Source
A3: Energy | B3: 2 | D3: Electricity | E3: 0.23314 | F3: 0.21233 | G3: 0.19338 | H3: 0.207074 | J3: kg CO2e/kWh | L3: T&D - UK electricity 2023&2022 = 0.01792 kg CO2e/kWh; 0.01879 in 2021
B4: 1 | D4: Gas | E4: 0.20374 | F4: 0.20297 | G4: 0.20227 | H4: 0.20267142 | J4: kg CO2e/kWh
B5: 1 | D5: Diesel | E5: 0.25568 | F5: 0.25165 | G5: 0.25631 | H5: 0.25409276 | J5: kg CO2e/kWh
B6: 1 | D6: Oil | E6: 0.2731 | F6: 0.27318 | G6: 0.27319 | H6: 0.27287699 | J6: kg CO2e/kWh
B7: 3 | D7: Transmission and distribution - T&D- UK electricity | E7: 0.02005 | F7: 0.01879 | G7: 0.01769 | H7: 0.017915111 | J7: kg CO2e/kWh | K7: Page 26 clarifies the transmission and distribution losses. https://assets.publishing.service.gov.uk/media/647f50dd103ca60013039a8a/2023-ghg-cf-methodology-paper.pdf#page27
B8: 3 | D8: Transmission and distribution - Distribution - district heat & steam | E8: 0.00908 | F8: 0.00899 | G8: 0.00899 | H8: 0.0094538779 | J8: kg CO2e/kWh
D9: Converstion factor - Other (i.e district heating) | E9: =Energy!B12 -> 0 | F9: =Energy!C12 -> 0 | G9: =Energy!D12 -> 0 | H9: =Energy!E12 -> 0 | J9: kg CO2e/kWh
B10: 1 | D10: On site energy generation (PV) | E10: =-E3 -> -0.23314 | F10: =-F3 -> -0.21233 | G10: =-G3 -> -0.19338 | H10: =-H3 -> -0.207074 | J10: kg CO2e/kWh | K10: Offsetting or avoiding Electricity use | O10: Is there any guidance on how to account for this one? Maybe it is the same as electricity??
A11: Water | B11: 3 | D11: Water | E11: 0.344 | F11: 0.149 | G11: 0.149 | H11: 0.17668455 | J11: kg CO2e/m3
B12: 3 | D12: Wastewater | E12: 0.708 | F12: 0.272 | G12: 0.272 | H12: 0.20131829 | J12: kg CO2e/m3
A13: Waste | B13: 3 | D13: Waste to landfill | E13: 458.1763 | F13: 467.0458 | G13: 467.00838 | H13: 520.33474 | J13: kg CO2e/tonne
B14: 3 | D14: Waste to energy | E14: 21.3167 | F14: 21.293566 | G14: 21.280807 | H14: 21.280807 | J14: kg CO2e/tonne
B15: 3 | D15: Waste to recycling | E15: 21.3167 | F15: 21.293566 | G15: 21.280807 | H15: 21.280807 | J15: kg CO2e/tonne
B16: 3 | D16: Waste to composting | E16: 10.2039 | F16: 8.9506977 | G16: 8.9105814 | H16: 8.9124217 | J16: kg CO2e/tonne
A17: Business Travel | B17: 3 | D17: Car (small) | Petrol | E17: 0.14836 | F17: 0.14946 | G17: 0.14652 | H17: 0.14079853 | J17: kg CO2e/km
B18: 3 | D18: Car (medium) | Petrol | E18: 0.18659 | F18: 0.18785 | G18: 0.1847 | H18: 0.17818853 | J18: kg CO2e/km
B19: 3 | D19: Car (large) | Petrol | E19: 0.27807 | F19: 0.27909 | G19: 0.27639 | H19: 0.27223853 | J19: kg CO2e/km
B20: 3 | D20: Car (average) | Petrol | E20: 0.1743 | F20: 0.17431 | G20: 0.17048 | H20: 0.16390853 | J20: kg CO2e/km
B21: 3 | D21: Car (small) | Diesel | E21: 0.13721 | F21: 0.13758 | G21: 0.13989414 | H21: 0.13930645 | J21: kg CO2e/km
B22: 3 | D22: Car (medium) | Diesel | E22: 0.16637 | F22: 0.16496 | G22: 0.16800414 | H22: 0.16715645 | J22: kg CO2e/km
B23: 3 | D23: Car (large) | Diesel | E23: 0.20419 | F23: 0.20721 | G23: 0.20953414 | H23: 0.20858645 | J23: kg CO2e/km
B24: 3 | D24: Car (average) | Diesel | E24: 0.16844 | F24: 0.16843 | G24: 0.17082414 | H24: 0.16982645 | J24: kg CO2e/km
B25: 3 | D25: Car (small) | Hybrid | E25: 0.10275 | F25: 0.10494 | G25: 0.10332 | H25: 0.10149886 | J25: kg CO2e/km
B26: 3 | D26: Car (medium) | Hybrid | E26: 0.10698 | F26: 0.10957 | G26: 0.10999 | H26: 0.10783 | J26: kg CO2e/km
B27: 3 | D27: Car (large) | Hybrid | E27: 0.1448 | F27: 0.15151 | G27: 0.15491 | H27: 0.15101 | J27: kg CO2e/km
B28: 3 | D28: Car (average) | Hybrid | E28: 0.11558 | F28: 0.11952 | G28: 0.12004 | H28: 0.11781 | J28: kg CO2e/km
B29: 3 | D29: Car (small) | Plug-in Hybrid | E29: 0.0586 | F29: 0.05568 | G29: 0.05255 | H29: 0.054022993 | J29: kg CO2e/km
